[2024-01-04T08:35:58.900+0000] {taskinstance.py:1957} INFO - Dependencies all met for dep_context=non-requeueable deps ti=<TaskInstance: job_process.get_indeed_data scheduled__2024-01-03T00:00:00+00:00 [queued]>
[2024-01-04T08:35:59.084+0000] {taskinstance.py:1957} INFO - Dependencies all met for dep_context=requeueable deps ti=<TaskInstance: job_process.get_indeed_data scheduled__2024-01-03T00:00:00+00:00 [queued]>
[2024-01-04T08:35:59.088+0000] {taskinstance.py:2171} INFO - Starting attempt 1 of 1
[2024-01-04T08:35:59.288+0000] {taskinstance.py:2192} INFO - Executing <Task(PythonOperator): get_indeed_data> on 2024-01-03 00:00:00+00:00
[2024-01-04T08:35:59.432+0000] {standard_task_runner.py:60} INFO - Started process 5655 to run task
[2024-01-04T08:35:59.514+0000] {standard_task_runner.py:87} INFO - Running: ['***', 'tasks', 'run', 'job_process', 'get_indeed_data', 'scheduled__2024-01-03T00:00:00+00:00', '--job-id', '182', '--raw', '--subdir', 'DAGS_FOLDER/job_process.py', '--cfg-path', '/tmp/tmp7x37eqi_']
[2024-01-04T08:35:59.585+0000] {standard_task_runner.py:88} INFO - Job 182: Subtask get_indeed_data
[2024-01-04T08:36:00.066+0000] {task_command.py:423} INFO - Running <TaskInstance: job_process.get_indeed_data scheduled__2024-01-03T00:00:00+00:00 [running]> on host f01482236d7b
[2024-01-04T08:36:00.967+0000] {taskinstance.py:2481} INFO - Exporting env vars: AIRFLOW_CTX_DAG_OWNER='***' AIRFLOW_CTX_DAG_ID='job_process' AIRFLOW_CTX_TASK_ID='get_indeed_data' AIRFLOW_CTX_EXECUTION_DATE='2024-01-03T00:00:00+00:00' AIRFLOW_CTX_TRY_NUMBER='1' AIRFLOW_CTX_DAG_RUN_ID='scheduled__2024-01-03T00:00:00+00:00'
[2024-01-04T08:36:06.721+0000] {taskinstance.py:2699} ERROR - Task failed with exception
Traceback (most recent call last):
  File "/home/airflow/.local/lib/python3.8/site-packages/urllib3/connectionpool.py", line 715, in urlopen
    httplib_response = self._make_request(
  File "/home/airflow/.local/lib/python3.8/site-packages/urllib3/connectionpool.py", line 467, in _make_request
    six.raise_from(e, None)
  File "<string>", line 3, in raise_from
  File "/home/airflow/.local/lib/python3.8/site-packages/urllib3/connectionpool.py", line 462, in _make_request
    httplib_response = conn.getresponse()
  File "/usr/local/lib/python3.8/http/client.py", line 1348, in getresponse
    response.begin()
  File "/usr/local/lib/python3.8/http/client.py", line 316, in begin
    version, status, reason = self._read_status()
  File "/usr/local/lib/python3.8/http/client.py", line 277, in _read_status
    line = str(self.fp.readline(_MAXLINE + 1), "iso-8859-1")
  File "/usr/local/lib/python3.8/socket.py", line 669, in readinto
    return self._sock.recv_into(b)
  File "/usr/local/lib/python3.8/ssl.py", line 1274, in recv_into
    return self.read(nbytes, buffer)
  File "/usr/local/lib/python3.8/ssl.py", line 1132, in read
    return self._sslobj.read(len, buffer)
ConnectionResetError: [Errno 104] Connection reset by peer

During handling of the above exception, another exception occurred:

Traceback (most recent call last):
  File "/home/airflow/.local/lib/python3.8/site-packages/requests/adapters.py", line 486, in send
    resp = conn.urlopen(
  File "/home/airflow/.local/lib/python3.8/site-packages/urllib3/connectionpool.py", line 799, in urlopen
    retries = retries.increment(
  File "/home/airflow/.local/lib/python3.8/site-packages/urllib3/util/retry.py", line 550, in increment
    raise six.reraise(type(error), error, _stacktrace)
  File "/home/airflow/.local/lib/python3.8/site-packages/urllib3/packages/six.py", line 769, in reraise
    raise value.with_traceback(tb)
  File "/home/airflow/.local/lib/python3.8/site-packages/urllib3/connectionpool.py", line 715, in urlopen
    httplib_response = self._make_request(
  File "/home/airflow/.local/lib/python3.8/site-packages/urllib3/connectionpool.py", line 467, in _make_request
    six.raise_from(e, None)
  File "<string>", line 3, in raise_from
  File "/home/airflow/.local/lib/python3.8/site-packages/urllib3/connectionpool.py", line 462, in _make_request
    httplib_response = conn.getresponse()
  File "/usr/local/lib/python3.8/http/client.py", line 1348, in getresponse
    response.begin()
  File "/usr/local/lib/python3.8/http/client.py", line 316, in begin
    version, status, reason = self._read_status()
  File "/usr/local/lib/python3.8/http/client.py", line 277, in _read_status
    line = str(self.fp.readline(_MAXLINE + 1), "iso-8859-1")
  File "/usr/local/lib/python3.8/socket.py", line 669, in readinto
    return self._sock.recv_into(b)
  File "/usr/local/lib/python3.8/ssl.py", line 1274, in recv_into
    return self.read(nbytes, buffer)
  File "/usr/local/lib/python3.8/ssl.py", line 1132, in read
    return self._sslobj.read(len, buffer)
urllib3.exceptions.ProtocolError: ('Connection aborted.', ConnectionResetError(104, 'Connection reset by peer'))

During handling of the above exception, another exception occurred:

Traceback (most recent call last):
  File "/home/airflow/.local/lib/python3.8/site-packages/airflow/models/taskinstance.py", line 433, in _execute_task
    result = execute_callable(context=context, **execute_callable_kwargs)
  File "/home/airflow/.local/lib/python3.8/site-packages/airflow/operators/python.py", line 199, in execute
    return_value = self.execute_callable()
  File "/home/airflow/.local/lib/python3.8/site-packages/airflow/operators/python.py", line 216, in execute_callable
    return self.python_callable(*self.op_args, **self.op_kwargs)
  File "/opt/airflow/dags/job_process.py", line 114, in get_indeed_data
    response = client.get('https://ma.indeed.com/jobs?q=offre+d%27emploi&fromage=1&vjk=39df24deb59b0e39&start=0')
  File "/home/airflow/.local/lib/python3.8/site-packages/scrapingbee/client.py", line 64, in get
    return self.request("GET", url, params=params, headers=headers, cookies=cookies, retries=retries, **kwargs)
  File "/home/airflow/.local/lib/python3.8/site-packages/scrapingbee/client.py", line 53, in request
    return session.request(method, spb_url, data=data, headers=headers, **kwargs)
  File "/home/airflow/.local/lib/python3.8/site-packages/requests/sessions.py", line 589, in request
    resp = self.send(prep, **send_kwargs)
  File "/home/airflow/.local/lib/python3.8/site-packages/requests/sessions.py", line 703, in send
    r = adapter.send(request, **kwargs)
  File "/home/airflow/.local/lib/python3.8/site-packages/requests/adapters.py", line 501, in send
    raise ConnectionError(err, request=request)
requests.exceptions.ConnectionError: ('Connection aborted.', ConnectionResetError(104, 'Connection reset by peer'))
[2024-01-04T08:36:07.413+0000] {taskinstance.py:1138} INFO - Marking task as FAILED. dag_id=job_process, task_id=get_indeed_data, execution_date=20240103T000000, start_date=20240104T083558, end_date=20240104T083607
[2024-01-04T08:36:07.924+0000] {standard_task_runner.py:107} ERROR - Failed to execute job 182 for task get_indeed_data (('Connection aborted.', ConnectionResetError(104, 'Connection reset by peer')); 5655)
[2024-01-04T08:36:08.070+0000] {local_task_job_runner.py:234} INFO - Task exited with return code 1
[2024-01-04T08:36:08.654+0000] {taskinstance.py:3281} INFO - 0 downstream tasks scheduled from follow-on schedule check
