[2023-12-18T09:10:29.143+0000] {taskinstance.py:1159} INFO - Dependencies all met for dep_context=non-requeueable deps ti=<TaskInstance: databricks_dag.trigger_databricks_notebook scheduled__2023-12-17T00:00:00+00:00 [queued]>
[2023-12-18T09:10:29.320+0000] {taskinstance.py:1159} INFO - Dependencies all met for dep_context=requeueable deps ti=<TaskInstance: databricks_dag.trigger_databricks_notebook scheduled__2023-12-17T00:00:00+00:00 [queued]>
[2023-12-18T09:10:29.322+0000] {taskinstance.py:1361} INFO - Starting attempt 1 of 1
[2023-12-18T09:10:29.429+0000] {taskinstance.py:1382} INFO - Executing <Task(DatabricksRunNowOperator): trigger_databricks_notebook> on 2023-12-17 00:00:00+00:00
[2023-12-18T09:10:29.553+0000] {standard_task_runner.py:84} INFO - Running: ['***', 'tasks', 'run', 'databricks_dag', 'trigger_databricks_notebook', 'scheduled__2023-12-17T00:00:00+00:00', '--job-id', '72', '--raw', '--subdir', 'DAGS_FOLDER/databricks_test.py', '--cfg-path', '/tmp/tmp3xfy8ygw']
[2023-12-18T09:10:29.557+0000] {standard_task_runner.py:85} INFO - Job 72: Subtask trigger_databricks_notebook
[2023-12-18T09:10:29.525+0000] {standard_task_runner.py:57} INFO - Started process 91 to run task
[2023-12-18T09:10:29.878+0000] {task_command.py:416} INFO - Running <TaskInstance: databricks_dag.trigger_databricks_notebook scheduled__2023-12-17T00:00:00+00:00 [running]> on host 0a5d71a5b82e
[2023-12-18T09:10:30.296+0000] {taskinstance.py:1662} INFO - Exporting env vars: AIRFLOW_CTX_DAG_OWNER='***' AIRFLOW_CTX_DAG_ID='databricks_dag' AIRFLOW_CTX_TASK_ID='trigger_databricks_notebook' AIRFLOW_CTX_EXECUTION_DATE='2023-12-17T00:00:00+00:00' AIRFLOW_CTX_TRY_NUMBER='1' AIRFLOW_CTX_DAG_RUN_ID='scheduled__2023-12-17T00:00:00+00:00'
[2023-12-18T09:10:30.349+0000] {base.py:73} INFO - Using connection ID 'databricks_default' for task execution.
[2023-12-18T09:10:30.350+0000] {databricks.py:170} INFO - Using token auth. 
[2023-12-18T09:10:30.568+0000] {databricks.py:224} ERROR - Attempt 1 API Request to Databricks failed with reason: HTTPSConnectionPool(host='adb-2256532642969647.7.azuredatabricks.net', port=443): Max retries exceeded with url: /api/2.0/jobs/run-now (Caused by NewConnectionError('<urllib3.connection.HTTPSConnection object at 0x7fede6f2e5b0>: Failed to establish a new connection: [Errno -2] Name or service not known'))
[2023-12-18T09:10:31.595+0000] {databricks.py:224} ERROR - Attempt 2 API Request to Databricks failed with reason: HTTPSConnectionPool(host='adb-2256532642969647.7.azuredatabricks.net', port=443): Max retries exceeded with url: /api/2.0/jobs/run-now (Caused by NewConnectionError('<urllib3.connection.HTTPSConnection object at 0x7fede6f2e610>: Failed to establish a new connection: [Errno -2] Name or service not known'))
[2023-12-18T09:10:32.642+0000] {databricks.py:224} ERROR - Attempt 3 API Request to Databricks failed with reason: HTTPSConnectionPool(host='adb-2256532642969647.7.azuredatabricks.net', port=443): Max retries exceeded with url: /api/2.0/jobs/run-now (Caused by NewConnectionError('<urllib3.connection.HTTPSConnection object at 0x7fede6f2e6a0>: Failed to establish a new connection: [Errno -2] Name or service not known'))
[2023-12-18T09:10:32.747+0000] {taskinstance.py:1937} ERROR - Task failed with exception
Traceback (most recent call last):
  File "/home/airflow/.local/lib/python3.8/site-packages/airflow/providers/databricks/operators/databricks.py", line 510, in execute
    self.run_id = hook.run_now(self.json)
  File "/home/airflow/.local/lib/python3.8/site-packages/airflow/providers/databricks/hooks/databricks.py", line 235, in run_now
    response = self._do_api_call(RUN_NOW_ENDPOINT, json)
  File "/home/airflow/.local/lib/python3.8/site-packages/airflow/providers/databricks/hooks/databricks.py", line 216, in _do_api_call
    raise AirflowException(
airflow.exceptions.AirflowException: API requests to Databricks failed 3 times. Giving up.
[2023-12-18T09:10:32.797+0000] {taskinstance.py:1400} INFO - Marking task as FAILED. dag_id=databricks_dag, task_id=trigger_databricks_notebook, execution_date=20231217T000000, start_date=20231218T091029, end_date=20231218T091032
[2023-12-18T09:10:32.884+0000] {standard_task_runner.py:104} ERROR - Failed to execute job 72 for task trigger_databricks_notebook (API requests to Databricks failed 3 times. Giving up.; 91)
[2023-12-18T09:10:32.953+0000] {local_task_job_runner.py:228} INFO - Task exited with return code 1
[2023-12-18T09:10:33.043+0000] {taskinstance.py:2778} INFO - 0 downstream tasks scheduled from follow-on schedule check
