[2023-12-16T12:08:35.881+0000] {taskinstance.py:1159} INFO - Dependencies all met for dep_context=non-requeueable deps ti=<TaskInstance: job_process.get_data manual__2023-12-16T12:07:57.853082+00:00 [queued]>
[2023-12-16T12:08:36.193+0000] {taskinstance.py:1159} INFO - Dependencies all met for dep_context=requeueable deps ti=<TaskInstance: job_process.get_data manual__2023-12-16T12:07:57.853082+00:00 [queued]>
[2023-12-16T12:08:36.199+0000] {taskinstance.py:1361} INFO - Starting attempt 1 of 1
[2023-12-16T12:08:36.401+0000] {taskinstance.py:1382} INFO - Executing <Task(PythonOperator): get_data> on 2023-12-16 12:07:57.853082+00:00
[2023-12-16T12:08:36.510+0000] {standard_task_runner.py:57} INFO - Started process 383 to run task
[2023-12-16T12:08:36.669+0000] {standard_task_runner.py:84} INFO - Running: ['***', 'tasks', 'run', 'job_process', 'get_data', 'manual__2023-12-16T12:07:57.853082+00:00', '--job-id', '43', '--raw', '--subdir', 'DAGS_FOLDER/job_process.py', '--cfg-path', '/tmp/tmpoxavi8fz']
[2023-12-16T12:08:36.709+0000] {standard_task_runner.py:85} INFO - Job 43: Subtask get_data
[2023-12-16T12:08:37.770+0000] {task_command.py:416} INFO - Running <TaskInstance: job_process.get_data manual__2023-12-16T12:07:57.853082+00:00 [running]> on host bbba14038308
[2023-12-16T12:08:39.763+0000] {taskinstance.py:1662} INFO - Exporting env vars: AIRFLOW_CTX_DAG_OWNER='***' AIRFLOW_CTX_DAG_ID='job_process' AIRFLOW_CTX_TASK_ID='get_data' AIRFLOW_CTX_EXECUTION_DATE='2023-12-16T12:07:57.853082+00:00' AIRFLOW_CTX_TRY_NUMBER='1' AIRFLOW_CTX_DAG_RUN_ID='manual__2023-12-16T12:07:57.853082+00:00'
[2023-12-16T12:12:14.774+0000] {selenium_manager.py:144} WARNING - Cache folder (/home/***/.cache/selenium) cannot be created: Permission denied (os error 13)
[2023-12-16T12:12:14.784+0000] {selenium_manager.py:144} WARNING - Cache folder (/home/***/.cache/selenium) cannot be created: Permission denied (os error 13)
[2023-12-16T12:12:14.785+0000] {selenium_manager.py:144} WARNING - Cache folder (/home/***/.cache/selenium) cannot be created: Permission denied (os error 13)
[2023-12-16T12:12:14.787+0000] {selenium_manager.py:144} WARNING - Cache folder (/home/***/.cache/selenium) cannot be created: Permission denied (os error 13)
[2023-12-16T12:12:14.795+0000] {taskinstance.py:1937} ERROR - Task failed with exception
Traceback (most recent call last):
  File "/home/airflow/.local/lib/python3.8/site-packages/selenium/webdriver/common/driver_finder.py", line 38, in get_path
    path = SeleniumManager().driver_location(options) if path is None else path
  File "/home/airflow/.local/lib/python3.8/site-packages/selenium/webdriver/common/selenium_manager.py", line 103, in driver_location
    output = self.run(args)
  File "/home/airflow/.local/lib/python3.8/site-packages/selenium/webdriver/common/selenium_manager.py", line 149, in run
    raise WebDriverException(f"Unsuccessful command executed: {command}.\n{result}{stderr}")
selenium.common.exceptions.WebDriverException: Message: Unsuccessful command executed: /home/airflow/.local/lib/python3.8/site-packages/selenium/webdriver/common/linux/selenium-manager --browser chrome --output json.
{'code': 65, 'message': 'Permission denied (os error 13)', 'driver_path': '', 'browser_path': ''}


The above exception was the direct cause of the following exception:

Traceback (most recent call last):
  File "/home/airflow/.local/lib/python3.8/site-packages/airflow/operators/python.py", line 192, in execute
    return_value = self.execute_callable()
  File "/home/airflow/.local/lib/python3.8/site-packages/airflow/operators/python.py", line 209, in execute_callable
    return self.python_callable(*self.op_args, **self.op_kwargs)
  File "/opt/airflow/dags/job_process.py", line 48, in get_glassdoor_job
    browser=webdriver.Chrome(options=options)
  File "/home/airflow/.local/lib/python3.8/site-packages/selenium/webdriver/chrome/webdriver.py", line 45, in __init__
    super().__init__(
  File "/home/airflow/.local/lib/python3.8/site-packages/selenium/webdriver/chromium/webdriver.py", line 49, in __init__
    self.service.path = DriverFinder.get_path(self.service, options)
  File "/home/airflow/.local/lib/python3.8/site-packages/selenium/webdriver/common/driver_finder.py", line 41, in get_path
    raise NoSuchDriverException(msg) from err
selenium.common.exceptions.NoSuchDriverException: Message: Unable to obtain driver for chrome using Selenium Manager.; For documentation on this error, please visit: https://www.selenium.dev/documentation/webdriver/troubleshooting/errors/driver_location

[2023-12-16T12:12:14.880+0000] {taskinstance.py:1400} INFO - Marking task as FAILED. dag_id=job_process, task_id=get_data, execution_date=20231216T120757, start_date=20231216T120835, end_date=20231216T121214
[2023-12-16T12:12:14.997+0000] {standard_task_runner.py:104} ERROR - Failed to execute job 43 for task get_data (Message: Unable to obtain driver for chrome using Selenium Manager.; For documentation on this error, please visit: https://www.selenium.dev/documentation/webdriver/troubleshooting/errors/driver_location
; 383)
[2023-12-16T12:12:15.161+0000] {local_task_job_runner.py:228} INFO - Task exited with return code 1
[2023-12-16T12:12:15.543+0000] {taskinstance.py:2778} INFO - 0 downstream tasks scheduled from follow-on schedule check
