[2023-12-17T22:04:35.339+0000] {taskinstance.py:1159} INFO - Dependencies all met for dep_context=non-requeueable deps ti=<TaskInstance: job_process.get_data manual__2023-12-17T22:04:28.775509+00:00 [queued]>
[2023-12-17T22:04:35.426+0000] {taskinstance.py:1159} INFO - Dependencies all met for dep_context=requeueable deps ti=<TaskInstance: job_process.get_data manual__2023-12-17T22:04:28.775509+00:00 [queued]>
[2023-12-17T22:04:35.428+0000] {taskinstance.py:1361} INFO - Starting attempt 1 of 1
[2023-12-17T22:04:35.939+0000] {taskinstance.py:1382} INFO - Executing <Task(PythonOperator): get_data> on 2023-12-17 22:04:28.775509+00:00
[2023-12-17T22:04:35.959+0000] {standard_task_runner.py:57} INFO - Started process 106 to run task
[2023-12-17T22:04:35.977+0000] {standard_task_runner.py:84} INFO - Running: ['***', 'tasks', 'run', 'job_process', 'get_data', 'manual__2023-12-17T22:04:28.775509+00:00', '--job-id', '65', '--raw', '--subdir', 'DAGS_FOLDER/job_process.py', '--cfg-path', '/tmp/tmp_njyiqub']
[2023-12-17T22:04:35.989+0000] {standard_task_runner.py:85} INFO - Job 65: Subtask get_data
[2023-12-17T22:04:36.141+0000] {task_command.py:416} INFO - Running <TaskInstance: job_process.get_data manual__2023-12-17T22:04:28.775509+00:00 [running]> on host 0a5d71a5b82e
[2023-12-17T22:04:36.346+0000] {taskinstance.py:1662} INFO - Exporting env vars: AIRFLOW_CTX_DAG_OWNER='***' AIRFLOW_CTX_DAG_ID='job_process' AIRFLOW_CTX_TASK_ID='get_data' AIRFLOW_CTX_EXECUTION_DATE='2023-12-17T22:04:28.775509+00:00' AIRFLOW_CTX_TRY_NUMBER='1' AIRFLOW_CTX_DAG_RUN_ID='manual__2023-12-17T22:04:28.775509+00:00'
[2023-12-17T22:04:40.895+0000] {logging_mixin.py:154} INFO - Response HTTP Status Code:  200
[2023-12-17T22:04:41.153+0000] {taskinstance.py:1937} ERROR - Task failed with exception
Traceback (most recent call last):
  File "/home/airflow/.local/lib/python3.8/site-packages/airflow/operators/python.py", line 192, in execute
    return_value = self.execute_callable()
  File "/home/airflow/.local/lib/python3.8/site-packages/airflow/operators/python.py", line 209, in execute_callable
    return self.python_callable(*self.op_args, **self.op_kwargs)
  File "/opt/airflow/dags/job_process.py", line 61, in get_data
    max_page = int(soup.select('ul[class="css-1g90gv6 eu4oa1w0"]')[0].find_all('li')[-2].text)
IndexError: list index out of range
[2023-12-17T22:04:41.177+0000] {taskinstance.py:1400} INFO - Marking task as FAILED. dag_id=job_process, task_id=get_data, execution_date=20231217T220428, start_date=20231217T220435, end_date=20231217T220441
[2023-12-17T22:04:41.214+0000] {standard_task_runner.py:104} ERROR - Failed to execute job 65 for task get_data (list index out of range; 106)
[2023-12-17T22:04:41.264+0000] {local_task_job_runner.py:228} INFO - Task exited with return code 1
[2023-12-17T22:04:41.292+0000] {taskinstance.py:2778} INFO - 0 downstream tasks scheduled from follow-on schedule check
