[2024-01-03T17:17:44.646+0000] {taskinstance.py:1957} INFO - Dependencies all met for dep_context=non-requeueable deps ti=<TaskInstance: job_process.transformed_data manual__2024-01-03T17:16:26.654093+00:00 [queued]>
[2024-01-03T17:17:44.726+0000] {taskinstance.py:1957} INFO - Dependencies all met for dep_context=requeueable deps ti=<TaskInstance: job_process.transformed_data manual__2024-01-03T17:16:26.654093+00:00 [queued]>
[2024-01-03T17:17:44.729+0000] {taskinstance.py:2171} INFO - Starting attempt 1 of 1
[2024-01-03T17:17:44.769+0000] {taskinstance.py:2192} INFO - Executing <Task(PythonOperator): transformed_data> on 2024-01-03 17:16:26.654093+00:00
[2024-01-03T17:17:44.784+0000] {standard_task_runner.py:60} INFO - Started process 5603 to run task
[2024-01-03T17:17:44.817+0000] {standard_task_runner.py:87} INFO - Running: ['***', 'tasks', 'run', 'job_process', 'transformed_data', 'manual__2024-01-03T17:16:26.654093+00:00', '--job-id', '180', '--raw', '--subdir', 'DAGS_FOLDER/job_process.py', '--cfg-path', '/tmp/tmp5n00el13']
[2024-01-03T17:17:44.828+0000] {standard_task_runner.py:88} INFO - Job 180: Subtask transformed_data
[2024-01-03T17:17:44.916+0000] {task_command.py:423} INFO - Running <TaskInstance: job_process.transformed_data manual__2024-01-03T17:16:26.654093+00:00 [running]> on host f01482236d7b
[2024-01-03T17:17:45.079+0000] {taskinstance.py:2481} INFO - Exporting env vars: AIRFLOW_CTX_DAG_OWNER='***' AIRFLOW_CTX_DAG_ID='job_process' AIRFLOW_CTX_TASK_ID='transformed_data' AIRFLOW_CTX_EXECUTION_DATE='2024-01-03T17:16:26.654093+00:00' AIRFLOW_CTX_TRY_NUMBER='1' AIRFLOW_CTX_DAG_RUN_ID='manual__2024-01-03T17:16:26.654093+00:00'
[2024-01-03T17:17:47.174+0000] {taskinstance.py:2699} ERROR - Task failed with exception
Traceback (most recent call last):
  File "/home/airflow/.local/lib/python3.8/site-packages/airflow/models/taskinstance.py", line 433, in _execute_task
    result = execute_callable(context=context, **execute_callable_kwargs)
  File "/home/airflow/.local/lib/python3.8/site-packages/airflow/operators/python.py", line 199, in execute
    return_value = self.execute_callable()
  File "/home/airflow/.local/lib/python3.8/site-packages/airflow/operators/python.py", line 216, in execute_callable
    return self.python_callable(*self.op_args, **self.op_kwargs)
  File "/opt/airflow/dags/job_process.py", line 202, in transform_data
    set_lon_lat(df_rekrute,dictionnary)
  File "/opt/airflow/dags/job_process.py", line 31, in set_lon_lat
    dataframe.loc[row[0],"lat/long"]= dictionnary[key]
  File "/home/airflow/.local/lib/python3.8/site-packages/pandas/core/indexing.py", line 849, in __setitem__
    iloc._setitem_with_indexer(indexer, value, self.name)
  File "/home/airflow/.local/lib/python3.8/site-packages/pandas/core/indexing.py", line 1791, in _setitem_with_indexer
    self._setitem_with_indexer(new_indexer, value, name)
  File "/home/airflow/.local/lib/python3.8/site-packages/pandas/core/indexing.py", line 1835, in _setitem_with_indexer
    self._setitem_with_indexer_split_path(indexer, value, name)
  File "/home/airflow/.local/lib/python3.8/site-packages/pandas/core/indexing.py", line 1891, in _setitem_with_indexer_split_path
    raise ValueError(
ValueError: Must have equal len keys and value when setting with an iterable
[2024-01-03T17:17:47.189+0000] {taskinstance.py:1138} INFO - Marking task as FAILED. dag_id=job_process, task_id=transformed_data, execution_date=20240103T171626, start_date=20240103T171744, end_date=20240103T171747
[2024-01-03T17:17:47.214+0000] {standard_task_runner.py:107} ERROR - Failed to execute job 180 for task transformed_data (Must have equal len keys and value when setting with an iterable; 5603)
[2024-01-03T17:17:47.245+0000] {local_task_job_runner.py:234} INFO - Task exited with return code 1
[2024-01-03T17:17:47.280+0000] {taskinstance.py:3281} INFO - 0 downstream tasks scheduled from follow-on schedule check
