[2024-01-03T07:03:37.382+0000] {scheduler_job_runner.py:781} ERROR - Executor reports task instance <TaskInstance: job_process.get_data scheduled__2024-01-02T00:00:00+00:00 [queued]> finished (failed) although the task says it's queued. (Info: None) Was the task killed externally?
