[2024-01-05T08:35:17.337+0000] {taskinstance.py:1957} INFO - Dependencies all met for dep_context=non-requeueable deps ti=<TaskInstance: job_process.transformed_data scheduled__2024-01-04T00:00:00+00:00 [queued]>
[2024-01-05T08:35:17.370+0000] {taskinstance.py:1957} INFO - Dependencies all met for dep_context=requeueable deps ti=<TaskInstance: job_process.transformed_data scheduled__2024-01-04T00:00:00+00:00 [queued]>
[2024-01-05T08:35:17.371+0000] {taskinstance.py:2171} INFO - Starting attempt 1 of 1
[2024-01-05T08:35:17.436+0000] {taskinstance.py:2192} INFO - Executing <Task(PythonOperator): transformed_data> on 2024-01-04 00:00:00+00:00
[2024-01-05T08:35:17.482+0000] {standard_task_runner.py:60} INFO - Started process 8179 to run task
[2024-01-05T08:35:17.495+0000] {standard_task_runner.py:87} INFO - Running: ['***', 'tasks', 'run', 'job_process', 'transformed_data', 'scheduled__2024-01-04T00:00:00+00:00', '--job-id', '188', '--raw', '--subdir', 'DAGS_FOLDER/job_process.py', '--cfg-path', '/tmp/tmpfyjhovan']
[2024-01-05T08:35:17.507+0000] {standard_task_runner.py:88} INFO - Job 188: Subtask transformed_data
[2024-01-05T08:35:17.647+0000] {task_command.py:423} INFO - Running <TaskInstance: job_process.transformed_data scheduled__2024-01-04T00:00:00+00:00 [running]> on host f01482236d7b
[2024-01-05T08:35:17.939+0000] {taskinstance.py:2481} INFO - Exporting env vars: AIRFLOW_CTX_DAG_OWNER='***' AIRFLOW_CTX_DAG_ID='job_process' AIRFLOW_CTX_TASK_ID='transformed_data' AIRFLOW_CTX_EXECUTION_DATE='2024-01-04T00:00:00+00:00' AIRFLOW_CTX_TRY_NUMBER='1' AIRFLOW_CTX_DAG_RUN_ID='scheduled__2024-01-04T00:00:00+00:00'
[2024-01-05T08:35:22.438+0000] {taskinstance.py:2699} ERROR - Task failed with exception
Traceback (most recent call last):
  File "/home/airflow/.local/lib/python3.8/site-packages/airflow/models/taskinstance.py", line 433, in _execute_task
    result = execute_callable(context=context, **execute_callable_kwargs)
  File "/home/airflow/.local/lib/python3.8/site-packages/airflow/operators/python.py", line 199, in execute
    return_value = self.execute_callable()
  File "/home/airflow/.local/lib/python3.8/site-packages/airflow/operators/python.py", line 216, in execute_callable
    return self.python_callable(*self.op_args, **self.op_kwargs)
  File "/opt/airflow/dags/job_process.py", line 181, in transform_data
    transformed_collection.insert_one(dict(row_rekrute[1]))
  File "/home/airflow/.local/lib/python3.8/site-packages/pymongo/collection.py", line 669, in insert_one
    self._insert_one(
  File "/home/airflow/.local/lib/python3.8/site-packages/pymongo/collection.py", line 609, in _insert_one
    self.__database.client._retryable_write(acknowledged, _insert_command, session)
  File "/home/airflow/.local/lib/python3.8/site-packages/pymongo/mongo_client.py", line 1523, in _retryable_write
    return self._retry_with_session(retryable, func, s, bulk)
  File "/home/airflow/.local/lib/python3.8/site-packages/pymongo/mongo_client.py", line 1421, in _retry_with_session
    return self._retry_internal(
  File "/home/airflow/.local/lib/python3.8/site-packages/pymongo/_csot.py", line 107, in csot_wrapper
    return func(self, *args, **kwargs)
  File "/home/airflow/.local/lib/python3.8/site-packages/pymongo/mongo_client.py", line 1453, in _retry_internal
    return _ClientConnectionRetryable(
  File "/home/airflow/.local/lib/python3.8/site-packages/pymongo/mongo_client.py", line 2315, in run
    return self._read() if self._is_read else self._write()
  File "/home/airflow/.local/lib/python3.8/site-packages/pymongo/mongo_client.py", line 2423, in _write
    return self._func(self._session, conn, self._retryable)  # type: ignore
  File "/home/airflow/.local/lib/python3.8/site-packages/pymongo/collection.py", line 607, in _insert_command
    _check_write_command_response(result)
  File "/home/airflow/.local/lib/python3.8/site-packages/pymongo/helpers.py", line 266, in _check_write_command_response
    _raise_last_write_error(write_errors)
  File "/home/airflow/.local/lib/python3.8/site-packages/pymongo/helpers.py", line 238, in _raise_last_write_error
    raise DuplicateKeyError(error.get("errmsg"), 11000, error)
pymongo.errors.DuplicateKeyError: E11000 duplicate key error collection: jobs_database.transformed_collection index: _id_ dup key: { _id: ObjectId('65956fecb94424c6b79fdec8') }, full error: {'index': 0, 'code': 11000, 'errmsg': "E11000 duplicate key error collection: jobs_database.transformed_collection index: _id_ dup key: { _id: ObjectId('65956fecb94424c6b79fdec8') }", 'keyPattern': {'_id': 1}, 'keyValue': {'_id': ObjectId('65956fecb94424c6b79fdec8')}}
[2024-01-05T08:35:22.462+0000] {taskinstance.py:1138} INFO - Marking task as FAILED. dag_id=job_process, task_id=transformed_data, execution_date=20240104T000000, start_date=20240105T083517, end_date=20240105T083522
[2024-01-05T08:35:22.483+0000] {standard_task_runner.py:107} ERROR - Failed to execute job 188 for task transformed_data (E11000 duplicate key error collection: jobs_database.transformed_collection index: _id_ dup key: { _id: ObjectId('65956fecb94424c6b79fdec8') }, full error: {'index': 0, 'code': 11000, 'errmsg': "E11000 duplicate key error collection: jobs_database.transformed_collection index: _id_ dup key: { _id: ObjectId('65956fecb94424c6b79fdec8') }", 'keyPattern': {'_id': 1}, 'keyValue': {'_id': ObjectId('65956fecb94424c6b79fdec8')}}; 8179)
[2024-01-05T08:35:22.552+0000] {local_task_job_runner.py:234} INFO - Task exited with return code 1
[2024-01-05T08:35:22.588+0000] {taskinstance.py:3281} INFO - 0 downstream tasks scheduled from follow-on schedule check
