[2024-01-03T17:12:07.354+0000] {taskinstance.py:1957} INFO - Dependencies all met for dep_context=non-requeueable deps ti=<TaskInstance: job_process.transformed_data manual__2024-01-03T17:10:21.052269+00:00 [queued]>
[2024-01-03T17:12:07.503+0000] {taskinstance.py:1957} INFO - Dependencies all met for dep_context=requeueable deps ti=<TaskInstance: job_process.transformed_data manual__2024-01-03T17:10:21.052269+00:00 [queued]>
[2024-01-03T17:12:07.511+0000] {taskinstance.py:2171} INFO - Starting attempt 1 of 1
[2024-01-03T17:12:07.592+0000] {taskinstance.py:2192} INFO - Executing <Task(PythonOperator): transformed_data> on 2024-01-03 17:10:21.052269+00:00
[2024-01-03T17:12:07.691+0000] {standard_task_runner.py:60} INFO - Started process 5277 to run task
[2024-01-03T17:12:07.730+0000] {standard_task_runner.py:87} INFO - Running: ['***', 'tasks', 'run', 'job_process', 'transformed_data', 'manual__2024-01-03T17:10:21.052269+00:00', '--job-id', '172', '--raw', '--subdir', 'DAGS_FOLDER/job_process.py', '--cfg-path', '/tmp/tmp576e1swb']
[2024-01-03T17:12:07.768+0000] {standard_task_runner.py:88} INFO - Job 172: Subtask transformed_data
[2024-01-03T17:12:07.894+0000] {task_command.py:423} INFO - Running <TaskInstance: job_process.transformed_data manual__2024-01-03T17:10:21.052269+00:00 [running]> on host f01482236d7b
[2024-01-03T17:12:08.137+0000] {taskinstance.py:2481} INFO - Exporting env vars: AIRFLOW_CTX_DAG_OWNER='***' AIRFLOW_CTX_DAG_ID='job_process' AIRFLOW_CTX_TASK_ID='transformed_data' AIRFLOW_CTX_EXECUTION_DATE='2024-01-03T17:10:21.052269+00:00' AIRFLOW_CTX_TRY_NUMBER='1' AIRFLOW_CTX_DAG_RUN_ID='manual__2024-01-03T17:10:21.052269+00:00'
[2024-01-03T17:12:10.640+0000] {taskinstance.py:2699} ERROR - Task failed with exception
Traceback (most recent call last):
  File "/home/airflow/.local/lib/python3.8/site-packages/airflow/models/taskinstance.py", line 433, in _execute_task
    result = execute_callable(context=context, **execute_callable_kwargs)
  File "/home/airflow/.local/lib/python3.8/site-packages/airflow/operators/python.py", line 199, in execute
    return_value = self.execute_callable()
  File "/home/airflow/.local/lib/python3.8/site-packages/airflow/operators/python.py", line 216, in execute_callable
    return self.python_callable(*self.op_args, **self.op_kwargs)
  File "/opt/airflow/dags/job_process.py", line 171, in transform_data
    with open("./utilities.json") as f:
FileNotFoundError: [Errno 2] No such file or directory: './utilities.json'
[2024-01-03T17:12:10.661+0000] {taskinstance.py:1138} INFO - Marking task as FAILED. dag_id=job_process, task_id=transformed_data, execution_date=20240103T171021, start_date=20240103T171207, end_date=20240103T171210
[2024-01-03T17:12:10.722+0000] {standard_task_runner.py:107} ERROR - Failed to execute job 172 for task transformed_data ([Errno 2] No such file or directory: './utilities.json'; 5277)
[2024-01-03T17:12:10.815+0000] {local_task_job_runner.py:234} INFO - Task exited with return code 1
[2024-01-03T17:12:10.874+0000] {taskinstance.py:3281} INFO - 0 downstream tasks scheduled from follow-on schedule check
