[2024-01-03T17:16:16.451+0000] {taskinstance.py:1957} INFO - Dependencies all met for dep_context=non-requeueable deps ti=<TaskInstance: job_process.transformed_data manual__2024-01-03T17:13:40.602949+00:00 [queued]>
[2024-01-03T17:16:16.466+0000] {taskinstance.py:1957} INFO - Dependencies all met for dep_context=requeueable deps ti=<TaskInstance: job_process.transformed_data manual__2024-01-03T17:13:40.602949+00:00 [queued]>
[2024-01-03T17:16:16.471+0000] {taskinstance.py:2171} INFO - Starting attempt 2 of 2
[2024-01-03T17:16:16.491+0000] {taskinstance.py:2192} INFO - Executing <Task(PythonOperator): transformed_data> on 2024-01-03 17:13:40.602949+00:00
[2024-01-03T17:16:16.504+0000] {standard_task_runner.py:60} INFO - Started process 5469 to run task
[2024-01-03T17:16:16.511+0000] {standard_task_runner.py:87} INFO - Running: ['***', 'tasks', 'run', 'job_process', 'transformed_data', 'manual__2024-01-03T17:13:40.602949+00:00', '--job-id', '177', '--raw', '--subdir', 'DAGS_FOLDER/job_process.py', '--cfg-path', '/tmp/tmp6pv88e37']
[2024-01-03T17:16:16.518+0000] {standard_task_runner.py:88} INFO - Job 177: Subtask transformed_data
[2024-01-03T17:16:16.601+0000] {task_command.py:423} INFO - Running <TaskInstance: job_process.transformed_data manual__2024-01-03T17:13:40.602949+00:00 [running]> on host f01482236d7b
[2024-01-03T17:16:16.839+0000] {taskinstance.py:2481} INFO - Exporting env vars: AIRFLOW_CTX_DAG_OWNER='***' AIRFLOW_CTX_DAG_ID='job_process' AIRFLOW_CTX_TASK_ID='transformed_data' AIRFLOW_CTX_EXECUTION_DATE='2024-01-03T17:13:40.602949+00:00' AIRFLOW_CTX_TRY_NUMBER='2' AIRFLOW_CTX_DAG_RUN_ID='manual__2024-01-03T17:13:40.602949+00:00'
[2024-01-03T17:16:18.979+0000] {taskinstance.py:2699} ERROR - Task failed with exception
Traceback (most recent call last):
  File "/home/airflow/.local/lib/python3.8/site-packages/airflow/models/taskinstance.py", line 433, in _execute_task
    result = execute_callable(context=context, **execute_callable_kwargs)
  File "/home/airflow/.local/lib/python3.8/site-packages/airflow/operators/python.py", line 199, in execute
    return_value = self.execute_callable()
  File "/home/airflow/.local/lib/python3.8/site-packages/airflow/operators/python.py", line 216, in execute_callable
    return self.python_callable(*self.op_args, **self.op_kwargs)
  File "/opt/airflow/dags/job_process.py", line 202, in transform_data
    set_lon_lat(df_rekrute,dictionnary)
  File "/opt/airflow/dags/job_process.py", line 31, in set_lon_lat
    dataframe.loc[row[0],"lat/long"]= dictionnary[key]
  File "/home/airflow/.local/lib/python3.8/site-packages/pandas/core/indexing.py", line 849, in __setitem__
    iloc._setitem_with_indexer(indexer, value, self.name)
  File "/home/airflow/.local/lib/python3.8/site-packages/pandas/core/indexing.py", line 1791, in _setitem_with_indexer
    self._setitem_with_indexer(new_indexer, value, name)
  File "/home/airflow/.local/lib/python3.8/site-packages/pandas/core/indexing.py", line 1835, in _setitem_with_indexer
    self._setitem_with_indexer_split_path(indexer, value, name)
  File "/home/airflow/.local/lib/python3.8/site-packages/pandas/core/indexing.py", line 1891, in _setitem_with_indexer_split_path
    raise ValueError(
ValueError: Must have equal len keys and value when setting with an iterable
[2024-01-03T17:16:19.009+0000] {taskinstance.py:1138} INFO - Marking task as FAILED. dag_id=job_process, task_id=transformed_data, execution_date=20240103T171340, start_date=20240103T171616, end_date=20240103T171619
[2024-01-03T17:16:19.042+0000] {standard_task_runner.py:107} ERROR - Failed to execute job 177 for task transformed_data (Must have equal len keys and value when setting with an iterable; 5469)
[2024-01-03T17:16:19.097+0000] {local_task_job_runner.py:234} INFO - Task exited with return code 1
[2024-01-03T17:16:19.135+0000] {taskinstance.py:3281} INFO - 0 downstream tasks scheduled from follow-on schedule check
