[2023-12-16T11:54:42.526+0000] {taskinstance.py:1159} INFO - Dependencies all met for dep_context=non-requeueable deps ti=<TaskInstance: job_process.get_data scheduled__2023-12-15T00:00:00+00:00 [queued]>
[2023-12-16T11:54:42.618+0000] {taskinstance.py:1159} INFO - Dependencies all met for dep_context=requeueable deps ti=<TaskInstance: job_process.get_data scheduled__2023-12-15T00:00:00+00:00 [queued]>
[2023-12-16T11:54:42.620+0000] {taskinstance.py:1361} INFO - Starting attempt 1 of 1
[2023-12-16T11:54:42.823+0000] {taskinstance.py:1382} INFO - Executing <Task(PythonOperator): get_data> on 2023-12-15 00:00:00+00:00
[2023-12-16T11:54:42.936+0000] {standard_task_runner.py:57} INFO - Started process 200 to run task
[2023-12-16T11:54:43.202+0000] {standard_task_runner.py:84} INFO - Running: ['***', 'tasks', 'run', 'job_process', 'get_data', 'scheduled__2023-12-15T00:00:00+00:00', '--job-id', '40', '--raw', '--subdir', 'DAGS_FOLDER/job_process.py', '--cfg-path', '/tmp/tmpz3222r1m']
[2023-12-16T11:54:43.222+0000] {standard_task_runner.py:85} INFO - Job 40: Subtask get_data
[2023-12-16T11:54:44.310+0000] {task_command.py:416} INFO - Running <TaskInstance: job_process.get_data scheduled__2023-12-15T00:00:00+00:00 [running]> on host bbba14038308
[2023-12-16T11:54:46.351+0000] {taskinstance.py:1662} INFO - Exporting env vars: AIRFLOW_CTX_DAG_OWNER='***' AIRFLOW_CTX_DAG_ID='job_process' AIRFLOW_CTX_TASK_ID='get_data' AIRFLOW_CTX_EXECUTION_DATE='2023-12-15T00:00:00+00:00' AIRFLOW_CTX_TRY_NUMBER='1' AIRFLOW_CTX_DAG_RUN_ID='scheduled__2023-12-15T00:00:00+00:00'
[2023-12-16T11:54:47.063+0000] {taskinstance.py:1937} ERROR - Task failed with exception
Traceback (most recent call last):
  File "/home/airflow/.local/lib/python3.8/site-packages/airflow/operators/python.py", line 192, in execute
    return_value = self.execute_callable()
  File "/home/airflow/.local/lib/python3.8/site-packages/airflow/operators/python.py", line 209, in execute_callable
    return self.python_callable(*self.op_args, **self.op_kwargs)
  File "/opt/airflow/dags/job_process.py", line 47, in get_glassdoor_job
    browser = webdriver.Chrome(service=s, options=options)
  File "/home/airflow/.local/lib/python3.8/site-packages/selenium/webdriver/chrome/webdriver.py", line 45, in __init__
    super().__init__(
  File "/home/airflow/.local/lib/python3.8/site-packages/selenium/webdriver/chromium/webdriver.py", line 50, in __init__
    self.service.start()
  File "/home/airflow/.local/lib/python3.8/site-packages/selenium/webdriver/common/service.py", line 102, in start
    self.assert_process_still_running()
  File "/home/airflow/.local/lib/python3.8/site-packages/selenium/webdriver/common/service.py", line 115, in assert_process_still_running
    raise WebDriverException(f"Service {self._path} unexpectedly exited. Status code was: {return_code}")
selenium.common.exceptions.WebDriverException: Message: Service /tmp/chrome/latest/chromedriver_linux64/chromedriver unexpectedly exited. Status code was: 127

[2023-12-16T11:54:47.327+0000] {taskinstance.py:1400} INFO - Marking task as FAILED. dag_id=job_process, task_id=get_data, execution_date=20231215T000000, start_date=20231216T115442, end_date=20231216T115447
[2023-12-16T11:54:47.484+0000] {standard_task_runner.py:104} ERROR - Failed to execute job 40 for task get_data (Message: Service /tmp/chrome/latest/chromedriver_linux64/chromedriver unexpectedly exited. Status code was: 127
; 200)
[2023-12-16T11:54:47.620+0000] {local_task_job_runner.py:228} INFO - Task exited with return code 1
[2023-12-16T11:54:47.878+0000] {taskinstance.py:2778} INFO - 0 downstream tasks scheduled from follow-on schedule check
