[2023-12-18T09:56:28.723+0000] {taskinstance.py:1159} INFO - Dependencies all met for dep_context=non-requeueable deps ti=<TaskInstance: job_process.get_data manual__2023-12-18T09:56:24.363535+00:00 [queued]>
[2023-12-18T09:56:28.737+0000] {taskinstance.py:1159} INFO - Dependencies all met for dep_context=requeueable deps ti=<TaskInstance: job_process.get_data manual__2023-12-18T09:56:24.363535+00:00 [queued]>
[2023-12-18T09:56:28.737+0000] {taskinstance.py:1361} INFO - Starting attempt 1 of 1
[2023-12-18T09:56:28.760+0000] {taskinstance.py:1382} INFO - Executing <Task(PythonOperator): get_data> on 2023-12-18 09:56:24.363535+00:00
[2023-12-18T09:56:28.774+0000] {standard_task_runner.py:57} INFO - Started process 711 to run task
[2023-12-18T09:56:28.780+0000] {standard_task_runner.py:84} INFO - Running: ['***', 'tasks', 'run', 'job_process', 'get_data', 'manual__2023-12-18T09:56:24.363535+00:00', '--job-id', '75', '--raw', '--subdir', 'DAGS_FOLDER/job_process.py', '--cfg-path', '/tmp/tmplrx0lfom']
[2023-12-18T09:56:28.786+0000] {standard_task_runner.py:85} INFO - Job 75: Subtask get_data
[2023-12-18T09:56:28.883+0000] {task_command.py:416} INFO - Running <TaskInstance: job_process.get_data manual__2023-12-18T09:56:24.363535+00:00 [running]> on host 0a5d71a5b82e
[2023-12-18T09:56:29.198+0000] {taskinstance.py:1662} INFO - Exporting env vars: AIRFLOW_CTX_DAG_OWNER='***' AIRFLOW_CTX_DAG_ID='job_process' AIRFLOW_CTX_TASK_ID='get_data' AIRFLOW_CTX_EXECUTION_DATE='2023-12-18T09:56:24.363535+00:00' AIRFLOW_CTX_TRY_NUMBER='1' AIRFLOW_CTX_DAG_RUN_ID='manual__2023-12-18T09:56:24.363535+00:00'
[2023-12-18T09:56:38.908+0000] {logging_mixin.py:154} INFO - Response HTTP Status Code:  500
[2023-12-18T09:56:44.643+0000] {logging_mixin.py:154} INFO - Response HTTP Status Code:  200
[2023-12-18T09:56:44.731+0000] {taskinstance.py:1937} ERROR - Task failed with exception
Traceback (most recent call last):
  File "/home/airflow/.local/lib/python3.8/site-packages/airflow/operators/python.py", line 192, in execute
    return_value = self.execute_callable()
  File "/home/airflow/.local/lib/python3.8/site-packages/airflow/operators/python.py", line 209, in execute_callable
    return self.python_callable(*self.op_args, **self.op_kwargs)
  File "/opt/airflow/dags/job_process.py", line 89, in get_data
    collection.insert({f"job_{num}":job})
  File "/home/airflow/.local/lib/python3.8/site-packages/pymongo/collection.py", line 3501, in __call__
    raise TypeError(
TypeError: 'Collection' object is not callable. If you meant to call the 'insert' method on a 'Database' object it is failing because no such method exists.
[2023-12-18T09:56:44.746+0000] {taskinstance.py:1400} INFO - Marking task as FAILED. dag_id=job_process, task_id=get_data, execution_date=20231218T095624, start_date=20231218T095628, end_date=20231218T095644
[2023-12-18T09:56:44.766+0000] {standard_task_runner.py:104} ERROR - Failed to execute job 75 for task get_data ('Collection' object is not callable. If you meant to call the 'insert' method on a 'Database' object it is failing because no such method exists.; 711)
[2023-12-18T09:56:44.811+0000] {local_task_job_runner.py:228} INFO - Task exited with return code 1
[2023-12-18T09:56:44.834+0000] {taskinstance.py:2778} INFO - 0 downstream tasks scheduled from follow-on schedule check
