[2023-12-17T22:02:37.578+0000] {taskinstance.py:1159} INFO - Dependencies all met for dep_context=non-requeueable deps ti=<TaskInstance: job_process.get_data scheduled__2023-12-16T00:00:00+00:00 [queued]>
[2023-12-17T22:02:37.621+0000] {taskinstance.py:1159} INFO - Dependencies all met for dep_context=requeueable deps ti=<TaskInstance: job_process.get_data scheduled__2023-12-16T00:00:00+00:00 [queued]>
[2023-12-17T22:02:37.622+0000] {taskinstance.py:1361} INFO - Starting attempt 1 of 1
[2023-12-17T22:02:37.677+0000] {taskinstance.py:1382} INFO - Executing <Task(PythonOperator): get_data> on 2023-12-16 00:00:00+00:00
[2023-12-17T22:02:37.694+0000] {standard_task_runner.py:57} INFO - Started process 79 to run task
[2023-12-17T22:02:37.714+0000] {standard_task_runner.py:84} INFO - Running: ['***', 'tasks', 'run', 'job_process', 'get_data', 'scheduled__2023-12-16T00:00:00+00:00', '--job-id', '64', '--raw', '--subdir', 'DAGS_FOLDER/job_process.py', '--cfg-path', '/tmp/tmpdsj5zqpi']
[2023-12-17T22:02:37.745+0000] {standard_task_runner.py:85} INFO - Job 64: Subtask get_data
[2023-12-17T22:02:37.964+0000] {task_command.py:416} INFO - Running <TaskInstance: job_process.get_data scheduled__2023-12-16T00:00:00+00:00 [running]> on host 0a5d71a5b82e
[2023-12-17T22:02:38.175+0000] {taskinstance.py:1662} INFO - Exporting env vars: AIRFLOW_CTX_DAG_OWNER='***' AIRFLOW_CTX_DAG_ID='job_process' AIRFLOW_CTX_TASK_ID='get_data' AIRFLOW_CTX_EXECUTION_DATE='2023-12-16T00:00:00+00:00' AIRFLOW_CTX_TRY_NUMBER='1' AIRFLOW_CTX_DAG_RUN_ID='scheduled__2023-12-16T00:00:00+00:00'
[2023-12-17T22:02:45.744+0000] {logging_mixin.py:154} INFO - Response HTTP Status Code:  200
[2023-12-17T22:02:45.910+0000] {taskinstance.py:1937} ERROR - Task failed with exception
Traceback (most recent call last):
  File "/home/airflow/.local/lib/python3.8/site-packages/airflow/operators/python.py", line 192, in execute
    return_value = self.execute_callable()
  File "/home/airflow/.local/lib/python3.8/site-packages/airflow/operators/python.py", line 209, in execute_callable
    return self.python_callable(*self.op_args, **self.op_kwargs)
  File "/opt/airflow/dags/job_process.py", line 61, in get_data
    max_page = int(soup.select('ul[class="css-1g90gv6 eu4oa1w0"]')[0].find_all('li')[-2].text)
IndexError: list index out of range
[2023-12-17T22:02:46.007+0000] {taskinstance.py:1400} INFO - Marking task as FAILED. dag_id=job_process, task_id=get_data, execution_date=20231216T000000, start_date=20231217T220237, end_date=20231217T220246
[2023-12-17T22:02:46.056+0000] {standard_task_runner.py:104} ERROR - Failed to execute job 64 for task get_data (list index out of range; 79)
[2023-12-17T22:02:46.154+0000] {local_task_job_runner.py:228} INFO - Task exited with return code 1
[2023-12-17T22:02:46.212+0000] {taskinstance.py:2778} INFO - 0 downstream tasks scheduled from follow-on schedule check
